2024-03-15 20:22:45,980 INFO    MainThread:7128 [wandb_setup.py:_flush():76] Current SDK version is 0.16.3
2024-03-15 20:22:45,980 INFO    MainThread:7128 [wandb_setup.py:_flush():76] Configure stats pid to 7128
2024-03-15 20:22:45,980 INFO    MainThread:7128 [wandb_setup.py:_flush():76] Loading settings from C:\Users\loreb\.config\wandb\settings
2024-03-15 20:22:45,980 INFO    MainThread:7128 [wandb_setup.py:_flush():76] Loading settings from c:\Users\loreb\Documents\IntellijProjects\PycharmProjects\DLA\wandb\settings
2024-03-15 20:22:45,980 INFO    MainThread:7128 [wandb_setup.py:_flush():76] Loading settings from environment variables: {}
2024-03-15 20:22:45,980 INFO    MainThread:7128 [wandb_setup.py:_flush():76] Applying setup settings: {'_disable_service': False}
2024-03-15 20:22:45,980 INFO    MainThread:7128 [wandb_setup.py:_flush():76] Inferring run settings from compute environment: {'program': '<python with no main file>'}
2024-03-15 20:22:45,981 INFO    MainThread:7128 [wandb_init.py:_log_setup():526] Logging user logs to c:\Users\loreb\Documents\IntellijProjects\PycharmProjects\DLA\wandb\run-20240315_202245-njcfv4ag\logs\debug.log
2024-03-15 20:22:45,981 INFO    MainThread:7128 [wandb_init.py:_log_setup():527] Logging internal logs to c:\Users\loreb\Documents\IntellijProjects\PycharmProjects\DLA\wandb\run-20240315_202245-njcfv4ag\logs\debug-internal.log
2024-03-15 20:22:45,981 INFO    MainThread:7128 [wandb_init.py:_jupyter_setup():472] configuring jupyter hooks <wandb.sdk.wandb_init._WandbInit object at 0x000001EC303FEAD0>
2024-03-15 20:22:45,981 INFO    MainThread:7128 [wandb_init.py:init():566] calling init triggers
2024-03-15 20:22:45,981 INFO    MainThread:7128 [wandb_init.py:init():573] wandb.init called with sweep_config: {}
config: {'learning_rate': 0.0001, 'architecture': 'MLP', 'dataset': 'MNIST', 'epochs': 100}
2024-03-15 20:22:45,981 INFO    MainThread:7128 [wandb_init.py:init():591] re-initializing run, found existing run on stack: fzghs9e7
2024-03-15 20:22:45,983 INFO    MainThread:7128 [wandb_run.py:_finish():1970] finishing run lorebaia/DLA Assigment 1/fzghs9e7
2024-03-15 20:22:45,983 INFO    MainThread:7128 [wandb_run.py:_atexit_cleanup():2210] got exitcode: 0
2024-03-15 20:22:45,984 INFO    MainThread:7128 [wandb_run.py:_restore():2193] restore
2024-03-15 20:22:45,984 INFO    MainThread:7128 [wandb_run.py:_restore():2199] restore done
2024-03-15 20:22:52,221 INFO    MainThread:7128 [wandb_run.py:_footer_history_summary_info():3866] rendering history
2024-03-15 20:22:52,221 INFO    MainThread:7128 [wandb_run.py:_footer_history_summary_info():3898] rendering summary
2024-03-15 20:22:52,227 INFO    MainThread:7128 [wandb_run.py:_footer_sync_info():3825] logging synced files
2024-03-15 20:22:52,278 INFO    MainThread:7128 [wandb_init.py:init():616] starting backend
2024-03-15 20:22:52,278 INFO    MainThread:7128 [wandb_init.py:init():620] setting up manager
2024-03-15 20:22:52,281 INFO    MainThread:7128 [backend.py:_multiprocessing_setup():105] multiprocessing start_methods=spawn, using: spawn
2024-03-15 20:22:52,281 INFO    MainThread:7128 [wandb_init.py:init():628] backend started and connected
2024-03-15 20:22:52,285 INFO    MainThread:7128 [wandb_run.py:_label_probe_notebook():1295] probe notebook
2024-03-15 20:22:52,285 INFO    MainThread:7128 [wandb_run.py:_label_probe_notebook():1305] Unable to probe notebook: 'NoneType' object has no attribute 'get'
2024-03-15 20:22:52,285 INFO    MainThread:7128 [wandb_init.py:init():720] updated telemetry
2024-03-15 20:22:52,325 INFO    MainThread:7128 [wandb_init.py:init():753] communicating run to backend with 90.0 second timeout
2024-03-15 20:22:54,038 INFO    MainThread:7128 [wandb_run.py:_on_init():2262] communicating current version
2024-03-15 20:22:54,594 INFO    MainThread:7128 [wandb_run.py:_on_init():2271] got version response upgrade_message: "wandb version 0.16.4 is available!  To upgrade, please run:\n $ pip install wandb --upgrade"

2024-03-15 20:22:54,594 INFO    MainThread:7128 [wandb_init.py:init():804] starting run threads in backend
2024-03-15 20:22:57,746 INFO    MainThread:7128 [wandb_run.py:_console_start():2241] atexit reg
2024-03-15 20:22:57,746 INFO    MainThread:7128 [wandb_run.py:_redirect():2096] redirect: wrap_raw
2024-03-15 20:22:57,746 INFO    MainThread:7128 [wandb_run.py:_redirect():2161] Wrapping output streams.
2024-03-15 20:22:57,746 INFO    MainThread:7128 [wandb_run.py:_redirect():2186] Redirects installed.
2024-03-15 20:22:57,746 INFO    MainThread:7128 [wandb_init.py:init():847] run started, returning control to user process
2024-03-15 20:28:12,220 INFO    MainThread:7128 [jupyter.py:save_ipynb():373] not saving jupyter notebook
2024-03-15 20:28:12,220 INFO    MainThread:7128 [wandb_init.py:_pause_backend():437] pausing backend
2024-03-15 20:28:36,695 INFO    MainThread:7128 [wandb_init.py:_resume_backend():442] resuming backend
2024-03-15 20:28:36,706 INFO    MainThread:7128 [wandb_setup.py:_flush():76] Current SDK version is 0.16.3
2024-03-15 20:28:36,707 INFO    MainThread:7128 [wandb_setup.py:_flush():76] Configure stats pid to 7128
2024-03-15 20:28:36,707 INFO    MainThread:7128 [wandb_setup.py:_flush():76] Loading settings from C:\Users\loreb\.config\wandb\settings
2024-03-15 20:28:36,707 INFO    MainThread:7128 [wandb_setup.py:_flush():76] Loading settings from c:\Users\loreb\Documents\IntellijProjects\PycharmProjects\DLA\wandb\settings
2024-03-15 20:28:36,707 INFO    MainThread:7128 [wandb_setup.py:_flush():76] Loading settings from environment variables: {}
2024-03-15 20:28:36,707 INFO    MainThread:7128 [wandb_setup.py:_flush():76] Applying setup settings: {'_disable_service': False}
2024-03-15 20:28:36,707 INFO    MainThread:7128 [wandb_setup.py:_flush():76] Inferring run settings from compute environment: {'program': '<python with no main file>'}
2024-03-15 20:28:36,707 INFO    MainThread:7128 [wandb_init.py:_log_setup():526] Logging user logs to c:\Users\loreb\Documents\IntellijProjects\PycharmProjects\DLA\wandb\run-20240315_202836-5u191jqo\logs\debug.log
2024-03-15 20:28:36,708 INFO    MainThread:7128 [wandb_init.py:_log_setup():527] Logging internal logs to c:\Users\loreb\Documents\IntellijProjects\PycharmProjects\DLA\wandb\run-20240315_202836-5u191jqo\logs\debug-internal.log
2024-03-15 20:28:36,708 INFO    MainThread:7128 [wandb_init.py:init():566] calling init triggers
2024-03-15 20:28:36,708 INFO    MainThread:7128 [wandb_init.py:init():573] wandb.init called with sweep_config: {}
config: {'learning_rate': 0.0001, 'architecture': 'MLP', 'dataset': 'MNIST', 'epochs': 100}
2024-03-15 20:28:36,708 INFO    MainThread:7128 [wandb_init.py:init():591] re-initializing run, found existing run on stack: njcfv4ag
2024-03-15 20:28:36,710 INFO    MainThread:7128 [wandb_run.py:_finish():1970] finishing run lorebaia/DLA Assigment 1/njcfv4ag
2024-03-15 20:28:36,710 INFO    MainThread:7128 [jupyter.py:save_history():445] not saving jupyter history
2024-03-15 20:28:36,710 INFO    MainThread:7128 [jupyter.py:save_ipynb():373] not saving jupyter notebook
2024-03-15 20:28:36,710 INFO    MainThread:7128 [wandb_init.py:_jupyter_teardown():454] cleaning up jupyter logic
2024-03-15 20:28:36,710 INFO    MainThread:7128 [wandb_run.py:_atexit_cleanup():2210] got exitcode: 0
2024-03-15 20:28:36,711 INFO    MainThread:7128 [wandb_run.py:_restore():2193] restore
2024-03-15 20:28:36,711 INFO    MainThread:7128 [wandb_run.py:_restore():2199] restore done
2024-03-15 20:30:58,775 WARNING MsgRouterThr:7128 [router.py:message_loop():77] message_loop has been closed
2024-03-15 20:31:03,718 INFO    MainThread:7128 [wandb_run.py:_restore():2193] restore
2024-03-15 20:31:03,718 INFO    MainThread:7128 [wandb_run.py:_restore():2199] restore done
2024-03-15 20:31:03,874 ERROR   MainThread:7128 [wandb_init.py:init():1204] error
Traceback (most recent call last):
  File "c:\src\anaconda3\envs\DLA\Lib\site-packages\wandb\sdk\wandb_run.py", line 2219, in _atexit_cleanup
    self._on_finish()
  File "c:\src\anaconda3\envs\DLA\Lib\site-packages\wandb\sdk\wandb_run.py", line 2474, in _on_finish
    _ = exit_handle.wait(timeout=-1, on_progress=self._on_progress_exit)
        ^^^^^^^^^^^^^^^^^^^^^^^^^^^^^^^^^^^^^^^^^^^^^^^^^^^^^^^^^^^^^^^^
  File "c:\src\anaconda3\envs\DLA\Lib\site-packages\wandb\sdk\lib\mailbox.py", line 298, in wait
    on_probe(probe_handle)
  File "c:\src\anaconda3\envs\DLA\Lib\site-packages\wandb\sdk\wandb_run.py", line 2436, in _on_probe_exit
    result = handle.wait(timeout=0, release=False)
             ^^^^^^^^^^^^^^^^^^^^^^^^^^^^^^^^^^^^^
  File "c:\src\anaconda3\envs\DLA\Lib\site-packages\wandb\sdk\lib\mailbox.py", line 281, in wait
    raise MailboxError("transport failed")
wandb.sdk.lib.mailbox.MailboxError: transport failed

During handling of the above exception, another exception occurred:

Traceback (most recent call last):
  File "c:\src\anaconda3\envs\DLA\Lib\site-packages\wandb\sdk\wandb_init.py", line 1176, in init
    run = wi.init()
          ^^^^^^^^^
  File "c:\src\anaconda3\envs\DLA\Lib\site-packages\wandb\sdk\wandb_init.py", line 601, in init
    latest_run.finish()
  File "c:\src\anaconda3\envs\DLA\Lib\site-packages\wandb\sdk\wandb_run.py", line 420, in wrapper
    return func(self, *args, **kwargs)
           ^^^^^^^^^^^^^^^^^^^^^^^^^^^
  File "c:\src\anaconda3\envs\DLA\Lib\site-packages\wandb\sdk\wandb_run.py", line 361, in wrapper
    return func(self, *args, **kwargs)
           ^^^^^^^^^^^^^^^^^^^^^^^^^^^
  File "c:\src\anaconda3\envs\DLA\Lib\site-packages\wandb\sdk\wandb_run.py", line 1961, in finish
    return self._finish(exit_code, quiet)
           ^^^^^^^^^^^^^^^^^^^^^^^^^^^^^^
  File "c:\src\anaconda3\envs\DLA\Lib\site-packages\wandb\sdk\wandb_run.py", line 1976, in _finish
    self._atexit_cleanup(exit_code=exit_code)
  File "c:\src\anaconda3\envs\DLA\Lib\site-packages\wandb\sdk\wandb_run.py", line 2230, in _atexit_cleanup
    self._backend.cleanup()
  File "c:\src\anaconda3\envs\DLA\Lib\site-packages\wandb\sdk\backend\backend.py", line 232, in cleanup
    self.interface.join()
  File "c:\src\anaconda3\envs\DLA\Lib\site-packages\wandb\sdk\interface\interface_shared.py", line 547, in join
    super().join()
  File "c:\src\anaconda3\envs\DLA\Lib\site-packages\wandb\sdk\interface\interface.py", line 710, in join
    _ = self._communicate_shutdown()
        ^^^^^^^^^^^^^^^^^^^^^^^^^^^^
  File "c:\src\anaconda3\envs\DLA\Lib\site-packages\wandb\sdk\interface\interface_shared.py", line 440, in _communicate_shutdown
    _ = self._communicate(record)
        ^^^^^^^^^^^^^^^^^^^^^^^^^
  File "c:\src\anaconda3\envs\DLA\Lib\site-packages\wandb\sdk\interface\interface_shared.py", line 300, in _communicate
    return self._communicate_async(rec, local=local).get(timeout=timeout)
           ^^^^^^^^^^^^^^^^^^^^^^^^^^^^^^^^^^^^^^^^^
  File "c:\src\anaconda3\envs\DLA\Lib\site-packages\wandb\sdk\interface\interface_sock.py", line 60, in _communicate_async
    future = self._router.send_and_receive(rec, local=local)
             ^^^^^^^^^^^^^^^^^^^^^^^^^^^^^^^^^^^^^^^^^^^^^^^
  File "c:\src\anaconda3\envs\DLA\Lib\site-packages\wandb\sdk\interface\router.py", line 94, in send_and_receive
    self._send_message(rec)
  File "c:\src\anaconda3\envs\DLA\Lib\site-packages\wandb\sdk\interface\router_sock.py", line 36, in _send_message
    self._sock_client.send_record_communicate(record)
  File "c:\src\anaconda3\envs\DLA\Lib\site-packages\wandb\sdk\lib\sock_client.py", line 216, in send_record_communicate
    self.send_server_request(server_req)
  File "c:\src\anaconda3\envs\DLA\Lib\site-packages\wandb\sdk\lib\sock_client.py", line 155, in send_server_request
    self._send_message(msg)
  File "c:\src\anaconda3\envs\DLA\Lib\site-packages\wandb\sdk\lib\sock_client.py", line 152, in _send_message
    self._sendall_with_error_handle(header + data)
  File "c:\src\anaconda3\envs\DLA\Lib\site-packages\wandb\sdk\lib\sock_client.py", line 130, in _sendall_with_error_handle
    sent = self._sock.send(data)
           ^^^^^^^^^^^^^^^^^^^^^
ConnectionResetError: [WinError 10054] Connessione in corso interrotta forzatamente dall'host remoto
